

























<?xml version="1.0" ?>
<!-- DO NOT EDIT: Generated from cloudship.sdf.jinja -->
<sdf version="1.5">

  <model name="cloudship">

    <self_collide>false</self_collide>
    <static>false</static>

    
    <link name="hull">
      <pose>0 0 1.25 0 0 0</pose>
      <inertial>
        <pose>0.20460772768687027 0 -0.6249821307201272 0 0 0</pose>
        <mass>8.065555581192736</mass>
        <inertia>
          <ixx>2.8015466924068972</ixx>
          <iyy>6.095429361688362</iyy>
          <izz>8.802036122021091</izz>
        </inertia>
      </inertial>

      <gravity>true</gravity>
      <self_collide>false</self_collide>
      <velocity_decay/>

      
      <visual name="hull_visual">
        <geometry>
          <mesh>
            <scale>2.35 0.7 0.95</scale>
            <uri>model://cloudship/meshes/ellipsoid.stl</uri>
          </mesh>
        </geometry>
      </visual>

      <collision name="hull_collision">
        <pose>0 0 0 0 0 0</pose>
        <geometry>
          <mesh>
            <scale>2.35 0.7 0.95</scale>
            <uri>model://cloudship/meshes/ellipsoid.stl</uri>
          </mesh>
        </geometry>
      </collision>

      
      <visual name="gondola_visual">
        <pose>0.65 0 -0.9129370469025024 0 0 0</pose>
        <geometry>
          <box>
            <size>0.4 0.17 0.2</size>
          </box>
        </geometry>
      </visual>

      <collision name="gondola_collision">
        <pose>0.65 0 -0.9629370469025025 0 0 0</pose>
        <geometry>
          <box>
            <size>0.4 0.17 0.1</size>
          </box>
        </geometry>
      </collision>

      
      <visual name="payload_visual">
      <pose>-0.05 0 -0.9497849462338037 1.5707963267948966 0 0</pose>
        <geometry>
          <cylinder>
            <radius>0.05</radius>
            <length>0.1</length>
          </cylinder>
        </geometry>
      </visual>

      <collision name="payload_collision">
      <pose>-0.05 0 -0.9497849462338037 1.5707963267948966 0 0</pose>
        <geometry>
          <cylinder>
            <radius>0.05</radius>
            <length>0.1</length>
          </cylinder>
        </geometry>
      </collision>

      
      <visual name="fin_top_visual">
  <pose>-1.5174999999999998 0 0.7253757377767631 0 0 0</pose>
  <geometry>
          <box>
            <size>0.465 0.01 0.78</size>
          </box>
        </geometry>
</visual>

<collision name="fin_top_collision">
  <pose>-1.5174999999999998 0 0.7253757377767631 0 0 0</pose>
  <geometry>
          <box>
            <size>0.465 0.01 0.78</size>
          </box>
        </geometry>
</collision>
      <visual name="fin_port_visual">
  <pose>-1.5174999999999998 0.5344873857302466 0 -1.5707963267948966 0 0</pose>
  <geometry>
          <box>
            <size>0.465 0.01 0.78</size>
          </box>
        </geometry>
</visual>

<collision name="fin_port_collision">
  <pose>-1.5174999999999998 0.5344873857302466 0 -1.5707963267948966 0 0</pose>
  <geometry>
          <box>
            <size>0.465 0.01 0.78</size>
          </box>
        </geometry>
</collision>
      <visual name="fin_sb_visual">
  <pose>-1.5174999999999998 -0.5344873857302466 0 1.5707963267948966 0 0</pose>
  <geometry>
          <box>
            <size>0.465 0.01 0.78</size>
          </box>
        </geometry>
</visual>

<collision name="fin_sb_collision">
  <pose>-1.5174999999999998 -0.5344873857302466 0 1.5707963267948966 0 0</pose>
  <geometry>
          <box>
            <size>0.465 0.01 0.78</size>
          </box>
        </geometry>
</collision>

      <visual name="fin_bottom_rotor_visual">
        <pose>-1.5174999999999998 0 -1.1153757377767632 0 0 0</pose>
        <geometry>
          <mesh>
            <scale>0.465 0.01 0.39</scale>
            <uri>model://cloudship/meshes/fin_prop.stl</uri>
          </mesh>
        </geometry>
      </visual>
      <visual name="fin_bottom_plate_visual">
        <pose>-1.5174999999999998 0 -0.5303757377767632 0 0 0</pose>
        <geometry>
          <box>
            <size>0.465 0.01 0.39</size>
          </box>
        </geometry>
      </visual>

      <collision name="fin_bottom_collision">
        <pose>-1.5174999999999998 0 -1.1153757377767632 0 0 0</pose>
        <geometry>
          <mesh>
            <scale>0.465 0.01 0.39</scale>
            <uri>model://cloudship/meshes/fin_prop.stl</uri>
          </mesh>
        </geometry>
      </collision>
    </link>

    
    <link name="stabilator">
      <pose>0.65 0 0.2870629530974975 0 0 0</pose><inertial>
        <mass>0.5</mass>
        <inertia>
          <ixx>0.0337625</ixx>
          <iyy>2.5e-05</iyy>
          <izz>0.0337625</izz>
        </inertia>
      </inertial>

      <gravity>false</gravity>
      <self_collide>false</self_collide>
      <velocity_decay/>

      <visual name="stabilator_visual">
        <pose>0 0 0 1.5707963267948966 0 0</pose>
        <geometry>
          <cylinder>
            <radius>0.01</radius>
            <length>0.9</length>
          </cylinder>
        </geometry>
      </visual>
      <visual name="port_prop_gaurd_visual">
        <pose>0.02 0.45 0 0 1.5707963267948966 0</pose>
        <geometry>
          <mesh>
            <scale>0.18161000000000002 0.18161000000000002 0.02</scale>
            <uri>model://cloudship/meshes/prop_gaurd.stl</uri>
          </mesh>
        </geometry>
      </visual>
      <visual name="sb_prop_gaurd_visual">
        <pose>0.02 -0.45 0 0 1.5707963267948966 0</pose>
        <geometry>
          <mesh>
            <scale>0.18161000000000002 0.18161000000000002 0.02</scale>
            <uri>model://cloudship/meshes/prop_gaurd.stl</uri>
          </mesh>
        </geometry>
      </visual>

      <collision name="stabilator_port_collision">
        <pose>0 0.2675 0 1.5707963267948966 0 0</pose>
        <geometry>
          <cylinder>
            <radius>0.01</radius>
            <length>0.365</length>
          </cylinder>
        </geometry>
      </collision>
      <collision name="stabilator_sb_collision">
        <pose>0 -0.2675 0 1.5707963267948966 0 0</pose>
        <geometry>
          <cylinder>
            <radius>0.01</radius>
            <length>0.365</length>
          </cylinder>
        </geometry>
      </collision>
    </link>

    <joint name='stabilator_joint' type='revolute'>
      <parent>hull</parent>
      <child>stabilator</child>
      <axis>
        <xyz>0 1 0</xyz>
        <limit>
          <lower>-3.141592653589793</lower>
          <upper>3.141592653589793</upper>
        </limit>
        <dynamics>
          <damping>0.1</damping>
        </dynamics>
      </axis>
      <physics>
        <ode>
          <implicit_spring_damper>1</implicit_spring_damper>
        </ode>
      </physics>
    </joint>

    
    <link name="rotor_1">
  <pose>0.67 0.45 0.2820629530974975 0 1.5707963267948966 0</pose>
  <inertial>
        <mass>0.0025</mass>
        <inertia>
          <ixx>1.0000000000000002e-06</ixx>
          <iyy>2.2798341666666663e-05</iyy>
          <izz>2.2798341666666663e-05</izz>
        </inertia>
      </inertial>

  <gravity>false</gravity>
  <self_collide>false</self_collide>
  <velocity_decay/>

  <visual name="rotor_1_visual">
    <geometry>
      <mesh>
        <scale>1.2842752129438761 1.2842752129438761 2.0855057351407718</scale>
        <uri>model://cloudship/meshes/prop_ccw.dae</uri>
      </mesh>
    </geometry>
  </visual>

  <collision name="rotor_1_collision">
    <geometry>
      <cylinder>
        <length>0.02</length>
        <radius>0.1651</radius>
      </cylinder>
    </geometry>
  </collision>
</link>

<joint name='rotor_1_joint' type='revolute'>
  <child>rotor_1</child>
  <parent>stabilator</parent>
  <axis>
    <xyz>0 0 1</xyz>
    <limit>
      <lower>-1e+16</lower>
      <upper>1e+16</upper>
    </limit>
    <dynamics>
      <spring_reference>0</spring_reference>
      <spring_stiffness>0</spring_stiffness>
    </dynamics>
  </axis>
</joint>


<plugin name='rotor_1_model' filename='libgazebo_motor_model.so'>
  <robotNamespace/>
  <jointName>rotor_1_joint</jointName>
  <linkName>rotor_1</linkName>
  <turningDirection>ccw</turningDirection>
  <timeConstantUp>0.05</timeConstantUp>
  <timeConstantDown>0.05</timeConstantDown>
  <maxRotVelocity>1500</maxRotVelocity>
  <motorConstant>7.063200000000001e-06</motorConstant>
  <momentConstant>0</momentConstant>
  <rotorDragCoefficient>0.000806428</rotorDragCoefficient>
  <rollingMomentCoefficient>1e-06</rollingMomentCoefficient>
  <commandSubTopic>/gazebo/command/motor_speed</commandSubTopic>
  <motorNumber>1</motorNumber>
  <motorSpeedPubTopic>/motor_speed/1</motorSpeedPubTopic>
  <rotorVelocitySlowdownSim>10</rotorVelocitySlowdownSim>
</plugin>
    <link name="rotor_2">
  <pose>0.67 -0.45 0.2870629530974975 0 1.5707963267948966 0</pose>
  <inertial>
        <mass>0.0025</mass>
        <inertia>
          <ixx>1.0000000000000002e-06</ixx>
          <iyy>2.2798341666666663e-05</iyy>
          <izz>2.2798341666666663e-05</izz>
        </inertia>
      </inertial>

  <gravity>false</gravity>
  <self_collide>false</self_collide>
  <velocity_decay/>

  <visual name="rotor_2_visual">
    <geometry>
      <mesh>
        <scale>1.2842752129438761 1.2842752129438761 2.0855057351407718</scale>
        <uri>model://cloudship/meshes/prop_cw.dae</uri>
      </mesh>
    </geometry>
  </visual>

  <collision name="rotor_2_collision">
    <geometry>
      <cylinder>
        <length>0.02</length>
        <radius>0.1651</radius>
      </cylinder>
    </geometry>
  </collision>
</link>

<joint name='rotor_2_joint' type='revolute'>
  <child>rotor_2</child>
  <parent>stabilator</parent>
  <axis>
    <xyz>0 0 1</xyz>
    <limit>
      <lower>-1e+16</lower>
      <upper>1e+16</upper>
    </limit>
    <dynamics>
      <spring_reference>0</spring_reference>
      <spring_stiffness>0</spring_stiffness>
    </dynamics>
  </axis>
</joint>


<plugin name='rotor_2_model' filename='libgazebo_motor_model.so'>
  <robotNamespace/>
  <jointName>rotor_2_joint</jointName>
  <linkName>rotor_2</linkName>
  <turningDirection>cw</turningDirection>
  <timeConstantUp>0.05</timeConstantUp>
  <timeConstantDown>0.05</timeConstantDown>
  <maxRotVelocity>1500</maxRotVelocity>
  <motorConstant>7.063200000000001e-06</motorConstant>
  <momentConstant>0</momentConstant>
  <rotorDragCoefficient>0.000806428</rotorDragCoefficient>
  <rollingMomentCoefficient>1e-06</rollingMomentCoefficient>
  <commandSubTopic>/gazebo/command/motor_speed</commandSubTopic>
  <motorNumber>2</motorNumber>
  <motorSpeedPubTopic>/motor_speed/2</motorSpeedPubTopic>
  <rotorVelocitySlowdownSim>10</rotorVelocitySlowdownSim>
</plugin>
    <link name="rotor_3">
  <pose>-1.5174999999999998 0 0.3296242622232368 1.5707963267948966 0 0</pose>
  <inertial>
        <mass>0.0015</mass>
        <inertia>
          <ixx>6.000000000000001e-07</ixx>
          <iyy>2.0661250000000005e-06</iyy>
          <izz>2.0661250000000005e-06</izz>
        </inertia>
      </inertial>

  <gravity>false</gravity>
  <self_collide>false</self_collide>
  <velocity_decay/>

  <visual name="rotor_3_visual">
    <geometry>
      <mesh>
        <scale>0.4939520049784139 0.4939520049784139 2.0855057351407718</scale>
        <uri>model://cloudship/meshes/prop_cw.dae</uri>
      </mesh>
    </geometry>
  </visual>

  <collision name="rotor_3_collision">
    <geometry>
      <cylinder>
        <length>0.02</length>
        <radius>0.0635</radius>
      </cylinder>
    </geometry>
  </collision>
</link>

<joint name='rotor_3_joint' type='revolute'>
  <child>rotor_3</child>
  <parent>hull</parent>
  <axis>
    <xyz>0 0 1</xyz>
    <limit>
      <lower>-1e+16</lower>
      <upper>1e+16</upper>
    </limit>
    <dynamics>
      <spring_reference>0</spring_reference>
      <spring_stiffness>0</spring_stiffness>
    </dynamics>
  </axis>
</joint>


<plugin name='rotor_3_model' filename='libgazebo_motor_model.so'>
  <robotNamespace/>
  <jointName>rotor_3_joint</jointName>
  <linkName>rotor_3</linkName>
  <turningDirection>cw</turningDirection>
  <timeConstantUp>0.025</timeConstantUp>
  <timeConstantDown>0.025</timeConstantDown>
  <maxRotVelocity>1500</maxRotVelocity>
  <motorConstant>8.720000000000001e-07</motorConstant>
  <momentConstant>0</momentConstant>
  <rotorDragCoefficient>0.000806428</rotorDragCoefficient>
  <rollingMomentCoefficient>1e-06</rollingMomentCoefficient>
  <commandSubTopic>/gazebo/command/motor_speed</commandSubTopic>
  <motorNumber>3</motorNumber>
  <motorSpeedPubTopic>/motor_speed/3</motorSpeedPubTopic>
  <rotorVelocitySlowdownSim>10</rotorVelocitySlowdownSim>
</plugin>

    
    
    <plugin name='buoyancy' filename='libgazebo_buoyancy_plugin.so'>
      <robotNamespace/>
      <linkName>hull</linkName>
      <linkVolume>6.546031892529931</linkVolume>
      <fluidDensity>1.225</fluidDensity>
    </plugin>

    
    <plugin name='aerodynamics' filename='libgazebo_lta_aerodynamics_plugin.so'>
      <robotNamespace/>
      <linkName>hull</linkName>
      <air_density>1.225</air_density>
      <length>4.7</length>
      <diameter>1.9</diameter>
      <m11>1.2028333602523749</m11>
      <m22>6.531829367371614</m22>
      <m26>0.4204930192349329</m26>
      <m33>6.531829367371614</m33>
      <m35>-0.4204930192349329</m35>
      <m44>0.05055269814975098</m44>
      <m53>-0.4204930192349329</m53>
      <m55>1.581060532654893</m55>
      <m62>0.4204930192349329</m62>
      <m66>1.581060532654893</m66>
      <cx1>0.02</cx1>
      <cx2>0.02</cx2>
      <cx3>0.02</cx3>
      <cy1>0.02</cy1>
      <cy2>0.02</cy2>
      <cy3>0.02</cy3>
      <cz1>0.02</cz1>
      <cz2>0.02</cz2>
      <cz3>0.02</cz3>
      <cl2>0.02</cl2>
      <cl3>0.0002</cl3>
      <cl4>0.0002</cl4>
      <cm1>0.02</cm1>
      <cm2>0.02</cm2>
      <cm3>0.02</cm3>
      <cm5>0.002</cm5>
      <cn1>0.02</cn1>
      <cn2>0.02</cn2>
      <cn3>0.02</cn3>
      <cn5>0.002</cn5>
    </plugin>

    
    <plugin name='gazebo_imu_plugin' filename='libgazebo_imu_plugin.so'>
      <robotNamespace/>
      <linkName>hull</linkName>
      <imuTopic>/imu</imuTopic>
      <gyroscopeNoiseDensity>0.0003394</gyroscopeNoiseDensity>
      <gyroscopeRandomWalk>3.8785e-05</gyroscopeRandomWalk>
      <gyroscopeBiasCorrelationTime>1000.0</gyroscopeBiasCorrelationTime>
      <gyroscopeTurnOnBiasSigma>0.0087</gyroscopeTurnOnBiasSigma>
      <accelerometerNoiseDensity>0.004</accelerometerNoiseDensity>
      <accelerometerRandomWalk>0.006</accelerometerRandomWalk>
      <accelerometerBiasCorrelationTime>300.0</accelerometerBiasCorrelationTime>
      <accelerometerTurnOnBiasSigma>0.196</accelerometerTurnOnBiasSigma>
    </plugin>

    
    <plugin name='gps_plugin' filename='libgazebo_gps_plugin.so'>
      <robotNamespace/>
      <gpsNoise>true</gpsNoise>
    </plugin>

    
    <plugin name='magnetometer_plugin' filename='libgazebo_magnetometer_plugin.so'>
      <robotNamespace/>
      <pubRate>20</pubRate>
      <noiseDensity>0.0004</noiseDensity>
      <randomWalk>6.4e-06</randomWalk>
      <biasCorrelationTime>600</biasCorrelationTime>
      <magTopic>/mag</magTopic>
    </plugin>

    
    <plugin name='barometer_plugin' filename='libgazebo_barometer_plugin.so'>
      <robotNamespace/>
      <pubRate>10</pubRate>
      <baroTopic>/baro</baroTopic>
    </plugin>

    
    <plugin name='mavlink_interface' filename='libgazebo_mavlink_interface.so'>
      <robotNamespace/>
      <imuSubTopic>/imu</imuSubTopic>
      <gpsSubTopic>/gps</gpsSubTopic>
      <magSubTopic>/mag</magSubTopic>
      <baroSubTopic>/baro</baroSubTopic>

      <mavlink_addr>INADDR_ANY</mavlink_addr>
      <mavlink_udp_port>14560</mavlink_udp_port>
      <mavlink_tcp_port>4560</mavlink_tcp_port>
      <serialEnabled>false</serialEnabled>
      <serialDevice>/dev/ttyACM0</serialDevice>
      <baudRate>921600</baudRate>
      <qgc_addr>INADDR_ANY</qgc_addr>
      <qgc_udp_port>14550</qgc_udp_port>

      <hil_mode>false</hil_mode>
      <hil_state_level>false</hil_state_level>
      <enable_lockstep>true</enable_lockstep>
      <use_tcp>true</use_tcp>

      <vehicle_is_tailsitter>false</vehicle_is_tailsitter>
      <send_vision_estimation>true</send_vision_estimation>
      <send_odometry>false</send_odometry>

      <control_channels>
        <channel name="stabilator">
          <input_index>0</input_index>
          <input_offset>-0.5</input_offset>
          <input_scaling>-3.141592653589793</input_scaling>
          <zero_position_disarmed>0</zero_position_disarmed>
          <zero_position_armed>0</zero_position_armed>
          <joint_control_type>position</joint_control_type>
          <joint_control_pid>
            <p>80</p>
            <i>0</i>
            <d>0</d>
            <iMax>0.0</iMax>
            <iMin>0.0</iMin>
            <cmdMax>1.5707963267948966</cmdMax>
            <cmdMin>-1.5707963267948966</cmdMin>
          </joint_control_pid>
          <joint_name>stabilator_joint</joint_name>
        </channel>
        <channel name='rotor_1'>
          <input_index>1</input_index>
          <input_offset>0</input_offset>
          <input_scaling>1500</input_scaling>
          <zero_position_disarmed>0</zero_position_disarmed>
          <zero_position_armed>0</zero_position_armed>
          <joint_control_type>velocity</joint_control_type>
          <joint_name>rotor_1_joint</joint_name>
        </channel>
        <channel name='rotor_2'>
          <input_index>2</input_index>
          <input_offset>0</input_offset>
          <input_scaling>1500</input_scaling>
          <zero_position_disarmed>0</zero_position_disarmed>
          <zero_position_armed>0</zero_position_armed>
          <joint_control_type>velocity</joint_control_type>
          <joint_name>rotor_2_joint</joint_name>
        </channel>
        <channel name='rotor_3'>
          <input_index>3</input_index>
          <input_offset>-0.5</input_offset>
          <input_scaling>-3000</input_scaling>
          <zero_position_disarmed>0</zero_position_disarmed>
          <zero_position_armed>0</zero_position_armed>
          <joint_control_type>velocity</joint_control_type>
          <joint_name>rotor_3_joint</joint_name>
        </channel>
      </control_channels>
    </plugin>

  </model>

</sdf>

<!-- vim: set et ft=xml fenc=utf-8 ff=unix sts=0 sw=2 ts=2 : -->