<?xml version="1.0"?>
<sdf version="1.6">
  <model name='raptor'>
    <link name='base_link'>
      <pose>0 0 0 0 0 1.57079632679</pose>
      <inertial>
        <pose>0 0 0 0 0 0</pose>
        <mass>1.5</mass>
        <inertia>
          <ixx>0.029125</ixx>
          <ixy>0</ixy>
          <ixz>0</ixz>
          <iyy>0.029125</iyy>
          <iyz>0</iyz>
          <izz>0.055225</izz>
        </inertia>
      </inertial>
      <self_collide>false</self_collide>
      <collision name='base_link_inertia_collision'>
        <pose>0 0 0 0 0 0</pose>
        <geometry>
          <mesh>
            <scale>0.001 0.001 0.001</scale>
            <uri>model://raptor/meshes/drone_hitbox.stl</uri>
          </mesh>
        </geometry>
        <surface>
          <contact>
            <ode>
              <min_depth>0.001</min_depth>
              <max_vel>0</max_vel>
            </ode>
          </contact>
          <friction>
          <friction>
            <ode>
              <mu>100</mu>
              <mu2>50</mu2>
            </ode>
          </friction>
          </friction>
        </surface>
      </collision>
      <visual name='base_link_inertia_visual'>
        <pose>0 0 0 0 0 0</pose>
        <geometry>
          <mesh>
            <scale>0.001 0.001 0.001</scale>
            <uri>model://raptor/meshes/drone_w_feets.stl</uri>
          </mesh>
        </geometry>
        <material>
          <script>
            <name>Gazebo/White</name>
            <uri>file://media/materials/scripts/gazebo.material</uri>
          </script>
        </material>
      </visual>
      <gravity>1</gravity>
      <velocity_decay/>
    </link>
    <include>
      <uri>model://imu</uri>
      <pose>0 0.03 0 0 0 0</pose>
      <name>imu</name>
    </include>
    <joint name='imu_joint' type='revolute'>
      <child>imu::link</child>
      <parent>base_link</parent>
      <axis>
        <xyz>1 0 0</xyz>
        <limit>
          <lower>0</lower>
          <upper>0</upper>
          <effort>0</effort>
          <velocity>0</velocity>
        </limit>
        <dynamics>
          <spring_reference>0</spring_reference>
          <spring_stiffness>0</spring_stiffness>
        </dynamics>
        <use_parent_model_frame>1</use_parent_model_frame>
      </axis>
    </joint>

 <link name='rotor_0'>
      <pose>0.13 -0.22 0.023 0 0 0</pose>
      <inertial>
        <pose>0 0 0 0 0 0</pose>
        <mass>0.005</mass>
        <inertia>
          <ixx>9.75e-07</ixx>
          <ixy>0</ixy>
          <ixz>0</ixz>
          <iyy>0.000273104</iyy>
          <iyz>0</iyz>
          <izz>0.000274004</izz>
        </inertia>
      </inertial>
      <collision name='rotor_0_collision'>
        <pose>0 0 0 0 0 0</pose>
        <geometry>
          <cylinder>
            <length>0.005</length>
            <radius>0.128</radius>
          </cylinder>
        </geometry>
        <surface>
          <contact>
            <ode/>
          </contact>
          <friction>
            <ode/>
          </friction>
        </surface>
      </collision>
      <visual name='rotor_0_visual'>
        <pose>0 0 0 0 0 0</pose>
        <geometry>
          <mesh>
            <scale>1 1 1</scale>
            <uri>model://iris/meshes/iris_prop_ccw.dae</uri>
          </mesh>
        </geometry>
        <material>
          <script>
            <name>Gazebo/Red</name>
            <uri>file://media/materials/scripts/gazebo.material</uri>
          </script>
        </material>
      </visual>
      <gravity>1</gravity>
      <velocity_decay/>
    </link>
    <joint name='rotor_0_joint' type='revolute'>
      <child>rotor_0</child>
      <parent>base_link</parent>
      <axis>
        <xyz>0 0 1</xyz>
        <limit>
          <lower>-1e+16</lower>
          <upper>1e+16</upper>
        </limit>
        <dynamics>
          <spring_reference>0</spring_reference>
          <spring_stiffness>0</spring_stiffness>
        </dynamics>
        <use_parent_model_frame>1</use_parent_model_frame>
      </axis>
    </joint>
    <link name='rotor_1'>
      <pose>-0.13 0.2 0.023 0 0 0</pose>
      <inertial>
        <pose>0 0 0 0 0 0</pose>
        <mass>0.005</mass>
        <inertia>
          <ixx>9.75e-07</ixx>
          <ixy>0</ixy>
          <ixz>0</ixz>
          <iyy>0.000273104</iyy>
          <iyz>0</iyz>
          <izz>0.000274004</izz>
        </inertia>
      </inertial>
      <collision name='rotor_1_collision'>
        <pose>0 0 0 0 0 0</pose>
        <geometry>
          <cylinder>
            <length>0.005</length>
            <radius>0.128</radius>
          </cylinder>
        </geometry>
        <surface>
          <contact>
            <ode/>
          </contact>
          <friction>
            <ode/>
          </friction>
        </surface>
      </collision>
      <visual name='rotor_1_visual'>
        <pose>0 0 0 0 0 0</pose>
        <geometry>
          <mesh>
            <scale>1 1 1</scale>
            <uri>model://iris/meshes/iris_prop_ccw.dae</uri>
          </mesh>
        </geometry>
        <material>
          <script>
            <name>Gazebo/Red</name>
            <uri>file://media/materials/scripts/gazebo.material</uri>
          </script>
        </material>
      </visual>
      <gravity>1</gravity>
      <velocity_decay/>
    </link>
    <joint name='rotor_1_joint' type='revolute'>
      <child>rotor_1</child>
      <parent>base_link</parent>
      <axis>
        <xyz>0 0 1</xyz>
        <limit>
          <lower>-1e+16</lower>
          <upper>1e+16</upper>
        </limit>
        <dynamics>
          <spring_reference>0</spring_reference>
          <spring_stiffness>0</spring_stiffness>
        </dynamics>
        <use_parent_model_frame>1</use_parent_model_frame>
      </axis>
    </joint>
    <link name='rotor_2'>
      <pose>0.13 0.22 0.023 0 0 0</pose>
      <inertial>
        <pose>0 0 0 0 0 0</pose>
        <mass>0.005</mass>
        <inertia>
          <ixx>9.75e-07</ixx>
          <ixy>0</ixy>
          <ixz>0</ixz>
          <iyy>0.000273104</iyy>
          <iyz>0</iyz>
          <izz>0.000274004</izz>
        </inertia>
      </inertial>
      <collision name='rotor_2_collision'>
        <pose>0 0 0 0 0 0</pose>
        <geometry>
          <cylinder>
            <length>0.005</length>
            <radius>0.128</radius>
          </cylinder>
        </geometry>
        <surface>
          <contact>
            <ode/>
          </contact>
          <friction>
            <ode/>
          </friction>
        </surface>
      </collision>
      <visual name='rotor_2_visual'>
        <pose>0 0 0 0 0 0</pose>
        <geometry>
          <mesh>
            <scale>1 1 1</scale>
            <uri>model://iris/meshes/iris_prop_cw.dae</uri>
          </mesh>
        </geometry>
        <material>
          <script>
            <name>Gazebo/Red</name>
            <uri>file://media/materials/scripts/gazebo.material</uri>
          </script>
        </material>
      </visual>
      <gravity>1</gravity>
      <velocity_decay/>
    </link>
    <joint name='rotor_2_joint' type='revolute'>
      <child>rotor_2</child>
      <parent>base_link</parent>
      <axis>
        <xyz>0 0 1</xyz>
        <limit>
          <lower>-1e+16</lower>
          <upper>1e+16</upper>
        </limit>
        <dynamics>
          <spring_reference>0</spring_reference>
          <spring_stiffness>0</spring_stiffness>
        </dynamics>
        <use_parent_model_frame>1</use_parent_model_frame>
      </axis>
    </joint>
    <link name='rotor_3'>
      <pose>-0.13 -0.2 0.023 0 0 0</pose>
      <inertial>
        <pose>0 0 0 0 0 0</pose>
        <mass>0.005</mass>
        <inertia>
          <ixx>9.75e-07</ixx>
          <ixy>0</ixy>
          <ixz>0</ixz>
          <iyy>0.000273104</iyy>
          <iyz>0</iyz>
          <izz>0.000274004</izz>
        </inertia>
      </inertial>
      <collision name='rotor_3_collision'>
        <pose>0 0 0 0 0 0</pose>
        <geometry>
          <cylinder>
            <length>0.005</length>
            <radius>0.128</radius>
          </cylinder>
        </geometry>
        <surface>
          <contact>
            <ode/>
          </contact>
          <friction>
            <ode/>
          </friction>
        </surface>
      </collision>
      <visual name='rotor_3_visual'>
        <pose>0 0 0 0 0 0</pose>
        <geometry>
          <mesh>
            <scale>1 1 1</scale>
            <uri>model://iris/meshes/iris_prop_cw.dae</uri>
          </mesh>
        </geometry>
        <material>
          <script>
            <name>Gazebo/Red</name>
            <uri>file://media/materials/scripts/gazebo.material</uri>
          </script>
        </material>
      </visual>
      <gravity>1</gravity>
      <velocity_decay/>
    </link>
    <joint name='rotor_3_joint' type='revolute'>
      <child>rotor_3</child>
      <parent>base_link</parent>
      <axis>
        <xyz>0 0 1</xyz>
        <limit>
          <lower>-1e+16</lower>
          <upper>1e+16</upper>
        </limit>
        <dynamics>
          <spring_reference>0</spring_reference>
          <spring_stiffness>0</spring_stiffness>
        </dynamics>
        <use_parent_model_frame>1</use_parent_model_frame>
      </axis>
    </joint>

    <!-- TEST GRIPPER -->
    <!-- <link name='leftGripperLink'>
      <pose>0.0 0.0 1.0 0 0 0</pose>
      <inertial>
        <pose>0 0 0 0 0 0</pose>
        <mass>0.005</mass>
        <inertia>
          <ixx>9.75e-07</ixx>
          <ixy>0</ixy>
          <ixz>0</ixz>
          <iyy>0.000273104</iyy>
          <iyz>0</iyz>
          <izz>0.000274004</izz>
        </inertia>
      </inertial>

      <visual name='leftGripperLink_visual'>
        <pose>0 0 0 0 0 0</pose>
        <geometry>
          <mesh>
            <scale>1 1 1</scale>
            <uri>model://iris/meshes/iris_prop_ccw.dae</uri>
          </mesh>
        </geometry>
        <material>
          <script>
            <name>Gazebo/Red</name>
            <uri>file://media/materials/scripts/gazebo.material</uri>
          </script>
        </material>
      </visual>
      <gravity>1</gravity>
      <velocity_decay/>
    </link>
    <joint name='leftGripperJoint' type='revolute'>
      <child>leftGripperLink</child>
      <parent>base_link</parent>
      <axis>
        <xyz>0 0 1</xyz>
        <limit>
          <lower>-1e+16</lower>
          <upper>1e+16</upper>
        </limit>
        <use_parent_model_frame>1</use_parent_model_frame>
      </axis>
    </joint> -->


    <plugin name='rosbag' filename='libgazebo_multirotor_base_plugin.so'>
      <robotNamespace/>
      <linkName>base_link</linkName>
      <rotorVelocitySlowdownSim>10</rotorVelocitySlowdownSim>
    </plugin>

    <!-- <plugin name='leftGripper_plugin' filename='libServoPlugin.so'>
      <subTopic>leftGripper_deg</subTopic>
      <linkName>leftGripperLink</linkName>
      <jointName>leftGripperJoint</jointName>
    </plugin> -->
    <plugin name='front_right_motor_model' filename='libgazebo_motor_model.so'>
      <robotNamespace/>
      <jointName>rotor_0_joint</jointName>
      <linkName>rotor_0</linkName>
      <turningDirection>ccw</turningDirection>
      <timeConstantUp>0.0125</timeConstantUp>
      <timeConstantDown>0.025</timeConstantDown>
      <maxRotVelocity>1100</maxRotVelocity>
      <motorConstant>5.84e-06</motorConstant>
      <momentConstant>0.06</momentConstant>
      <commandSubTopic>/gazebo/command/motor_speed</commandSubTopic>
      <motorNumber>0</motorNumber>
      <rotorDragCoefficient>0.000175</rotorDragCoefficient>
      <rollingMomentCoefficient>1e-06</rollingMomentCoefficient>
      <motorSpeedPubTopic>/motor_speed/0</motorSpeedPubTopic>
      <rotorVelocitySlowdownSim>10</rotorVelocitySlowdownSim>
    </plugin>
    <plugin name='back_left_motor_model' filename='libgazebo_motor_model.so'>
      <robotNamespace/>
      <jointName>rotor_1_joint</jointName>
      <linkName>rotor_1</linkName>
      <turningDirection>ccw</turningDirection>
      <timeConstantUp>0.0125</timeConstantUp>
      <timeConstantDown>0.025</timeConstantDown>
      <maxRotVelocity>1100</maxRotVelocity>
      <motorConstant>5.84e-06</motorConstant>
      <momentConstant>0.06</momentConstant>
      <commandSubTopic>/gazebo/command/motor_speed</commandSubTopic>
      <motorNumber>1</motorNumber>
      <rotorDragCoefficient>0.000175</rotorDragCoefficient>
      <rollingMomentCoefficient>1e-06</rollingMomentCoefficient>
      <motorSpeedPubTopic>/motor_speed/1</motorSpeedPubTopic>
      <rotorVelocitySlowdownSim>10</rotorVelocitySlowdownSim>
    </plugin>
    <plugin name='front_left_motor_model' filename='libgazebo_motor_model.so'>
      <robotNamespace/>
      <jointName>rotor_2_joint</jointName>
      <linkName>rotor_2</linkName>
      <turningDirection>cw</turningDirection>
      <timeConstantUp>0.0125</timeConstantUp>
      <timeConstantDown>0.025</timeConstantDown>
      <maxRotVelocity>1100</maxRotVelocity>
      <motorConstant>5.84e-06</motorConstant>
      <momentConstant>0.06</momentConstant>
      <commandSubTopic>/gazebo/command/motor_speed</commandSubTopic>
      <motorNumber>2</motorNumber>
      <rotorDragCoefficient>0.000175</rotorDragCoefficient>
      <rollingMomentCoefficient>1e-06</rollingMomentCoefficient>
      <motorSpeedPubTopic>/motor_speed/2</motorSpeedPubTopic>
      <rotorVelocitySlowdownSim>10</rotorVelocitySlowdownSim>
    </plugin>
    <plugin name='back_right_motor_model' filename='libgazebo_motor_model.so'>
      <robotNamespace/>
      <jointName>rotor_3_joint</jointName>
      <linkName>rotor_3</linkName>
      <turningDirection>cw</turningDirection>
      <timeConstantUp>0.0125</timeConstantUp>
      <timeConstantDown>0.025</timeConstantDown>
      <maxRotVelocity>1100</maxRotVelocity>
      <motorConstant>5.84e-06</motorConstant>
      <momentConstant>0.06</momentConstant>
      <commandSubTopic>/gazebo/command/motor_speed</commandSubTopic>
      <motorNumber>3</motorNumber>
      <rotorDragCoefficient>0.000175</rotorDragCoefficient>
      <rollingMomentCoefficient>1e-06</rollingMomentCoefficient>
      <motorSpeedPubTopic>/motor_speed/3</motorSpeedPubTopic>
      <rotorVelocitySlowdownSim>10</rotorVelocitySlowdownSim>
    </plugin>
    <include>
      <uri>model://gps</uri>
      <pose> -0.03 0 0 0 0</pose>
      <name>gps0</name>
    </include>
    <joint name='gps0_joint' type='fixed'>
      <child>gps0::link</child>
      <parent>base_link</parent>
    </joint>
    <include>
      <uri>model://magnetometer</uri>
      <pose>0 0 0 0 0 0</pose>
      <name>mag</name>
    </include>
    <joint name='mag_joint' type='fixed'>
      <child>mag::link</child>
      <parent>base_link</parent>
    </joint>
    <plugin name='groundtruth_plugin' filename='libgazebo_groundtruth_plugin.so'>
      <robotNamespace/>
    </plugin>
    <plugin name='barometer_plugin' filename='libgazebo_barometer_plugin.so'>
      <robotNamespace/>
      <pubRate>50</pubRate>
      <baroTopic>/baro</baroTopic>
      <baroDriftPaPerSec>0</baroDriftPaPerSec>
    </plugin>
    <plugin name='mavlink_interface' filename='libgazebo_mavlink_interface.so'>
      <robotNamespace/>
      <imuSubTopic>/imu</imuSubTopic>
      <magSubTopic>/mag</magSubTopic>
      <baroSubTopic>/baro</baroSubTopic>
      <mavlink_addr>INADDR_ANY</mavlink_addr>
      <mavlink_tcp_port>4560</mavlink_tcp_port>
      <mavlink_udp_port>14560</mavlink_udp_port>
      <serialEnabled>0</serialEnabled>
      <serialDevice>/dev/ttyACM0</serialDevice>
      <baudRate>921600</baudRate>
      <qgc_addr>INADDR_ANY</qgc_addr>
      <qgc_udp_port>14550</qgc_udp_port>
      <sdk_addr>INADDR_ANY</sdk_addr>
      <sdk_udp_port>14540</sdk_udp_port>
      <hil_mode>0</hil_mode>
      <hil_state_level>0</hil_state_level>
      <send_vision_estimation>0</send_vision_estimation>
      <send_odometry>1</send_odometry>
      <enable_lockstep>1</enable_lockstep>
      <use_tcp>1</use_tcp>
      <motorSpeedCommandPubTopic>/gazebo/command/motor_speed</motorSpeedCommandPubTopic>
      <control_channels>
        <channel name='rotor1'>
          <input_index>0</input_index>
          <input_offset>0</input_offset>
          <input_scaling>1000</input_scaling>
          <zero_position_disarmed>0</zero_position_disarmed>
          <zero_position_armed>100</zero_position_armed>
          <joint_control_type>velocity</joint_control_type>
        </channel>
        <channel name='rotor2'>
          <input_index>1</input_index>
          <input_offset>0</input_offset>
          <input_scaling>1000</input_scaling>
          <zero_position_disarmed>0</zero_position_disarmed>
          <zero_position_armed>100</zero_position_armed>
          <joint_control_type>velocity</joint_control_type>
        </channel>
        <channel name='rotor3'>
          <input_index>2</input_index>
          <input_offset>0</input_offset>
          <input_scaling>1000</input_scaling>
          <zero_position_disarmed>0</zero_position_disarmed>
          <zero_position_armed>100</zero_position_armed>
          <joint_control_type>velocity</joint_control_type>
        </channel>
        <channel name='rotor4'>
          <input_index>3</input_index>
          <input_offset>0</input_offset>
          <input_scaling>1000</input_scaling>
          <zero_position_disarmed>0</zero_position_disarmed>
          <zero_position_armed>100</zero_position_armed>
          <joint_control_type>velocity</joint_control_type>
        </channel>
        <channel name='rotor5'>
          <input_index>4</input_index>
          <input_offset>1</input_offset>
          <input_scaling>324.6</input_scaling>
          <zero_position_disarmed>0</zero_position_disarmed>
          <zero_position_armed>0</zero_position_armed>
          <joint_control_type>velocity</joint_control_type>
          <joint_control_pid>
            <p>0.1</p>
            <i>0</i>
            <d>0</d>
            <iMax>0.0</iMax>
            <iMin>0.0</iMin>
            <cmdMax>2</cmdMax>
            <cmdMin>-2</cmdMin>
          </joint_control_pid>
          <joint_name>zephyr_delta_wing::propeller_joint</joint_name>
        </channel>
        <channel name='rotor6'>
          <input_index>5</input_index>
          <input_offset>0</input_offset>
          <input_scaling>0.524</input_scaling>
          <zero_position_disarmed>0</zero_position_disarmed>
          <zero_position_armed>0</zero_position_armed>
          <joint_control_type>position</joint_control_type>
          <joint_name>zephyr_delta_wing::flap_left_joint</joint_name>
          <joint_control_pid>
            <d>0</d>
            <iMax>0</iMax>
            <iMin>0</iMin>
            <cmdMax>20</cmdMax>
            <cmdMin>-20</cmdMin>
          </joint_control_pid>
        </channel>
        <channel name='rotor7'>
          <input_index>6</input_index>
          <input_offset>0</input_offset>
          <input_scaling>0.524</input_scaling>
          <zero_position_disarmed>0</zero_position_disarmed>
          <zero_position_armed>0</zero_position_armed>
          <joint_control_type>position</joint_control_type>
          <joint_name>zephyr_delta_wing::flap_right_joint</joint_name>
          <joint_control_pid>
            <p>10.0</p>
            <i>0</i>
            <d>0</d>
            <iMax>0</iMax>
            <iMin>0</iMin>
            <cmdMax>20</cmdMax>
            <cmdMin>-20</cmdMin>
          </joint_control_pid>
        </channel>
        <channel name='rotor8'>
          <input_index>7</input_index>
          <input_offset>0</input_offset>
          <input_scaling>0.524</input_scaling>
          <zero_position_disarmed>0</zero_position_disarmed>
          <zero_position_armed>0</zero_position_armed>
          <joint_control_type>position</joint_control_type>
        </channel>
      </control_channels>
    </plugin>
    <static>0</static>

    <!-- GRIPPER -->
    <link name='gripper_base_link'>

      <pose relative_to='base_link'> 0.0 0.0 -0.05 0.0 1.5707963 0.0</pose><!--1.5707963 1.5707963 -0.02 -->
      <inertial>
        <pose>0 0 0 0 0 0</pose>
        <mass>0.00000001</mass>
        <inertia>
          <ixx>0.000001</ixx>
          <ixy>0.0</ixy>
          <iyy>0.000001</iyy>
          <ixz>0.0</ixz>
          <iyz>0.0</iyz>
          <izz>0.000001</izz>
        </inertia>
      </inertial>
      <self_collide> false</self_collide>
      <collision name='gripper_base_link_inertia_collision'>
        <pose>0 0 0 0 0 0</pose>
        <geometry>
          <box>
            <size>0.02617 0.02689 0.04064</size>
          </box>
        </geometry>
        <surface>
          <contact>
            <ode>
              <min_depth>0.001</min_depth>
              <max_vel>0</max_vel>
            </ode>
          </contact>
          <friction>
            <ode/>
          </friction>
        </surface>
      </collision>
      <visual name='gripper_base_link_inertia_visual'>
        <pose>0 0 0 0 0 0</pose>
        <geometry>
          <mesh>
            <scale>0.001 0.001 0.001</scale>
            <uri>model://raptor/meshes/gripper_base.stl</uri>
          </mesh>
        </geometry>
        <material>
          <script>
            <name>Gazebo/White</name>
            <uri>file://media/materials/scripts/gazebo.material</uri>
          </script>
        </material>
      </visual>
      <gravity>1</gravity>
      <velocity_decay/>
    </link>

    <joint name='gripper_base_joint' type='fixed'>
      <child>gripper_base_link</child>
      <parent>base_link</parent>
      <axis>
        <xyz>0 0 1</xyz>
        <limit>
          <lower>-1e+16</lower>
          <upper>1e+16</upper>
        </limit>
        <use_parent_model_frame>1</use_parent_model_frame>
      </axis>
    </joint>

    <link name='gripper_left_link'>
      <pose relative_to='gripper_base_link'> 0.05666 0.0 -0.03465 0.0 0.0 0.0</pose>
      <inertial>
        <pose>0 0 0 0 0 0</pose>
        <mass>0.00000001</mass>
        <inertia>
          <ixx>0.000001</ixx>
          <ixy>0.0</ixy>
          <iyy>0.000001</iyy>
          <ixz>0.0</ixz>
          <iyz>0.0</iyz>
          <izz>0.000001</izz>
        </inertia>
      </inertial>
      <self_collide>true</self_collide>
      <collision name='gripper_left_link_inertia_collision'>
        <pose>0.03417 0 0.02 0 0 0</pose>
        <geometry>
          <box>
            <size>0.1 0.08 0.03</size>
          </box>
        </geometry>
        <surface>
          <contact>
            <ode>
              <min_depth>0.001</min_depth>
              <max_vel>100000</max_vel>
            </ode>
          </contact>
           <friction>
            <ode>
              <mu>10000000</mu>
              <mu2>10000000</mu2>
            </ode>
          </friction>
        </surface>
      </collision>
      <visual name='gripper_left_link_inertia_visual'>
      <!-- <pose>0.03417 0 0.02 0 0 0</pose> -->
        <pose>0 0 0 0 0 0</pose>
        <geometry>
          <!-- <box>
            <size>0.1 0.08 0.03</size>
          </box> -->
          <mesh>
            <scale>0.001 0.001 0.001</scale>
            <uri>model://raptor/meshes/gripper_1.stl</uri>
          </mesh>
        </geometry>
        <material>
          <script>
            <name>Gazebo/Red</name>
            <uri>file://media/materials/scripts/gazebo.material</uri>
          </script>
        </material>
      </visual>
      <gravity>1</gravity>
      <velocity_decay/>
    </link>

    <joint name='gripper_left_joint' type='revolute'>
      <child>gripper_left_link</child>
      <parent>gripper_base_link</parent>
      <axis>
        <xyz>0 1 0</xyz>
        <limit>
          <lower>-1e+16</lower>
          <upper>1e+16</upper>
        </limit>
        <use_parent_model_frame>0</use_parent_model_frame>
      </axis>
      <pose relative_to='gripper_base_link'> 0.01248 0.0 -0.02006 0.0 0.0 0.0</pose>
    </joint>

    <plugin name='gripper_left_plugin' filename='libServoPlugin.so'>
      <subTopic>leftGripper_deg</subTopic>
      <linkName>gripper_left_link</linkName>
      <jointName>gripper_left_joint</jointName>
      <initialAngle>90.0</initialAngle>
      <turningDirection>0</turningDirection> <!-- 0: clockwise, 1: counterclockwise -->
    </plugin>

    <link name='gripper_right_link'>
      <!--x: -0.01248 -0.04418 = -0.05666  -->
      <!--z: 0.02006 + 0.01459 = -0.03465 -->
      <pose relative_to='gripper_base_link'> 0.05666 0.0 0.03465 0.0 0.0 0.0</pose>
      <inertial>
        <pose>0 0 0 0 0 0</pose>
        <mass>0.00000001</mass>
        <inertia>
          <ixx>0.000001</ixx>
          <ixy>0.0</ixy>
          <iyy>0.000001</iyy>
          <ixz>0.0</ixz>
          <iyz>0.0</iyz>
          <izz>0.000001</izz>
        </inertia>
      </inertial>
      <self_collide>true</self_collide>
      <collision name='gripper_right_link_inertia_collision'>
        <pose>0.03417 0 -0.02 0 0 0</pose>
        <geometry>
          <box>
            <size>0.1 0.08 0.03</size>
          </box>
        </geometry>
        <surface>
          <contact>
            <ode>
              <min_depth>0.001</min_depth>
              <max_vel>100000</max_vel>
            </ode>
          </contact>
          <friction>
            <ode>
              <mu>10000000</mu>
              <mu2>10000000</mu2>
            </ode>
          </friction>
        </surface>
      </collision>
      <visual name='gripper_right_link_inertia_visual'>
        <pose>0 0 0 0 0 0</pose>
        <!-- <pose>0.03417 0 -0.02 0 0 0</pose> -->
        <geometry>
          <!-- <box>
            <size>0.1 0.08 0.03</size>
          </box> -->
          <mesh>
            <scale>0.001 0.001 0.001</scale>
            <uri>model://raptor/meshes/gripper_2.stl</uri>
          </mesh>
        </geometry>
        <material>
          <script>
            <name>Gazebo/Red</name>
            <uri>file://media/materials/scripts/gazebo.material</uri>
          </script>
        </material>
      </visual>
      <gravity>1</gravity>
      <velocity_decay/>
    </link>

    <joint name='gripper_right_joint' type='revolute'>
      <child>gripper_right_link</child>
      <parent>gripper_base_link</parent>
      <axis>
        <xyz>0 1 0</xyz>
        <limit>
          <lower>-1e+16</lower>
          <upper>1e+16</upper>
        </limit>
        <use_parent_model_frame>0</use_parent_model_frame>
      </axis>
      <pose relative_to='gripper_base_link'> 0.01248 0.0 0.02006 0.0 0.0 0.0</pose>
    </joint>

    <plugin name='gripper_right_plugin' filename='libServoPlugin.so'>
      <subTopic>rightGripper_deg</subTopic>
      <linkName>gripper_right_link</linkName>
      <jointName>gripper_right_joint</jointName>
      <initialAngle>90.0</initialAngle>
      <turningDirection>1</turningDirection> <!-- 0: clockwise, 1: counterclockwise -->
    </plugin>


       <!-- REALSENSE Facing downwards -->
 <model name="realsense_camera_down">
     <plugin name="realsense_down_plugin" filename="libRealSensePlugin.so">
      <pubTopic>realsense_down</pubTopic>
    </plugin>
    <pose relative_to='base_link'>0.0 0.0 -0.08 0.0 1.57079632679 0.0</pose> <!---0.1-->

    <joint name='realsense_joint' type='fixed'>
      <child>realsense_down_link</child>
      <parent>base_link</parent>
      <axis>
        <xyz>0 0 1</xyz>
        <limit>
          <lower>-1e+16</lower>
          <upper>1e+16</upper>
        </limit>
        <use_parent_model_frame>1</use_parent_model_frame>
      </axis>
    </joint>

    <link name="realsense_down_link">
       <inertial>
        <pose>0 0 0 0 0 0</pose>
        <mass>0.00000001</mass>
        <inertia>
          <ixx>0.000001</ixx>
          <ixy>0.0</ixy>
          <iyy>0.000001</iyy>
          <ixz>0.0</ixz>
          <iyz>0.0</iyz>
          <izz>0.000001</izz>
        </inertia>
      </inertial>
      <self_collide>false</self_collide>
      <kinematic>0</kinematic>
      <gravity>1</gravity>
      <visual name="visual">
        <geometry>
          <mesh>
            <uri>model://realsense_camera/meshes/realsense.dae</uri>
          </mesh>
        </geometry>
      </visual>
      <collision name='collision'>
       <pose>0 0 0 0 0 0</pose>
        <geometry>
          <box>
            <size>0.0001 0.0001 0.0001</size>
          </box>
        </geometry>
        <surface>
          <friction>
            <ode>
            </ode>
          </friction>
        </surface>
      <!-- <laser_retro>0</laser_retro>
        <max_contacts>10</max_contacts>
        <pose>0 0 0 0 -0 0</pose>
        <geometry>
          <box>
            <size>0.0078 0.130 0.0192</size>
          </box>
        </geometry>
        <surface>
          <friction>
            <ode>
              <mu>1</mu>
              <mu2>1</mu2>
              <fdir1>0 0 0</fdir1>
              <slip1>0</slip1>
              <slip2>0</slip2>
            </ode>
          </friction>
          <bounce>
            <restitution_coefficient>0</restitution_coefficient>
            <threshold>1e+06</threshold>
          </bounce>
          <contact>
            <collide_without_contact>0</collide_without_contact>
            <collide_without_contact_bitmask>1</collide_without_contact_bitmask>
            <collide_bitmask>1</collide_bitmask>
            <ode>
              <soft_cfm>0</soft_cfm>
              <soft_erp>0.2</soft_erp>
              <kp>1e+13</kp>
              <kd>1</kd>
              <max_vel>0.01</max_vel>
              <min_depth>0</min_depth>
            </ode>
            <bullet>
              <split_impulse>1</split_impulse>
              <split_impulse_penetration_threshold>-0.01</split_impulse_penetration_threshold>
              <soft_cfm>0</soft_cfm>
              <soft_erp>0.2</soft_erp>
              <kp>1e+13</kp>
              <kd>1</kd>
            </bullet>
          </contact>
        </surface> -->
      </collision>
      <sensor name="realsense_camera_down_color" type="camera">
        <pose>0 -0.046 0.004 0 0 0</pose>x
        <camera name="__default__">
          <horizontal_fov>1.047</horizontal_fov>
          <image>
            <width>640</width>
            <height>480</height>
            <format>RGB_INT8</format>
          </image>
          <clip>
            <near>0.1</near>
            <far>100</far>
          </clip>
          <noise>
            <type>gaussian</type>
            <mean>0.0</mean>
            <stddev>0.007</stddev>
          </noise>
        </camera>
        <always_on>1</always_on>
        <update_rate>60</update_rate>
        <visualize>1</visualize>
      </sensor>
      <sensor name="realsense_camera_down_ired1" type="camera">
        <pose>0 -0.06 0.004 0 0 0</pose>
        <camera name="__default__">
          <horizontal_fov>1.047</horizontal_fov>
          <image>
            <width>640</width>
            <height>480</height>
            <format>L_INT8</format>
          </image>
          <clip>
            <near>0.1</near>
            <far>100</far>
          </clip>
          <noise>
            <type>gaussian</type>
            <mean>0.0</mean>
            <stddev>0.007</stddev>
          </noise>
        </camera>
        <always_on>1</always_on>
        <update_rate>60</update_rate>
        <visualize>0</visualize>
      </sensor>
      <sensor name="realsense_camera_down_ired2" type="camera">
        <pose>0 0.01 0.004 0 0 0</pose>
        <camera name="__default__">
          <horizontal_fov>1.047</horizontal_fov>
          <image>
            <width>640</width>
            <height>480</height>
            <format>L_INT8</format>
          </image>
          <clip>
            <near>0.1</near>
            <far>100</far>
          </clip>
          <noise>
            <type>gaussian</type>
            <mean>0.0</mean>
            <stddev>0.007</stddev>
          </noise>
        </camera>
        <always_on>1</always_on>
        <update_rate>60</update_rate>
        <visualize>0</visualize>
      </sensor>
      <sensor name="realsense_camera_down_depth" type="depth">
        <pose>0 -0.03 0.004 0 0 0</pose>
        <camera name="__default__">
          <horizontal_fov>1.047</horizontal_fov>
          <image>
            <width>640</width>
            <height>480</height>
          </image>
          <clip>
            <near>0.1</near>
            <far>100</far>
          </clip>
          <noise>
            <type>gaussian</type>
            <mean>0.0</mean>
            <stddev>0.007</stddev>
          </noise>
        </camera>
        <always_on>1</always_on>
        <update_rate>60</update_rate>
        <visualize>0</visualize>
      </sensor>
    </link>
  </model>


  <!-- REALSENSE Facing forwards -->
 <model name="realsense_camera_front">
     <plugin name="realsense_front_plugin" filename="libRealSensePlugin.so">
      <pubTopic>realsense_front</pubTopic>
    </plugin>
    <pose relative_to='base_link'>0.07 0.0 0 -0.01  0.78539816339 0.0</pose> <!-- .08 0.0 -0.05-->

    <joint name='realsense_joint' type='fixed'>
      <child>realsense_front_link</child>
      <parent>base_link</parent>
      <axis>
        <xyz>0 0 1</xyz>
        <limit>
          <lower>-1e+16</lower>
          <upper>1e+16</upper>
        </limit>
        <use_parent_model_frame>1</use_parent_model_frame>
      </axis>
    </joint>

    <link name="realsense_front_link">
      <inertial>
        <pose>0 0 0 0 0 0</pose>
        <mass>0.00000001</mass>
        <inertia>
          <ixx>0.000001</ixx>
          <ixy>0.0</ixy>
          <iyy>0.000001</iyy>
          <ixz>0.0</ixz>
          <iyz>0.0</iyz>
          <izz>0.000001</izz>
        </inertia>
      </inertial>
      <self_collide>false</self_collide>
      <kinematic>0</kinematic>
      <gravity>1</gravity>
      <visual name="visual">
        <geometry>
          <mesh>
            <uri>model://realsense_camera/meshes/realsense.dae</uri>
          </mesh>
        </geometry>
      </visual>
      <collision name='collision'>
        <pose>0 0 0 0 0 0</pose>
        <geometry>
          <box>
            <size>0.0001 0.0001 0.0001</size>
          </box>
        </geometry>
        <surface>
          <friction>
            <ode>
            </ode>
          </friction>
        </surface>
        <!-- <laser_retro>0</laser_retro>
        <max_contacts>10</max_contacts>
        <pose>0 0 0 0 -0 0</pose>
        <geometry>
          <box>
            <size>0.0078 0.130 0.0192</size>
          </box>
        </geometry>
        <surface>
          <friction>
            <ode>
              <mu>1</mu>
              <mu2>1</mu2>
              <fdir1>0 0 0</fdir1>
              <slip1>0</slip1>
              <slip2>0</slip2>
            </ode>
          </friction>
          <bounce>
            <restitution_coefficient>0</restitution_coefficient>
            <threshold>1e+06</threshold>
          </bounce>
          <contact>
            <collide_without_contact>0</collide_without_contact>
            <collide_without_contact_bitmask>1</collide_without_contact_bitmask>
            <collide_bitmask>1</collide_bitmask>
            <ode>
              <soft_cfm>0</soft_cfm>
              <soft_erp>0.2</soft_erp>
              <kp>1e+13</kp>
              <kd>1</kd>
              <max_vel>0.01</max_vel>
              <min_depth>0</min_depth>
            </ode>
            <bullet>
              <split_impulse>1</split_impulse>
              <split_impulse_penetration_threshold>-0.01</split_impulse_penetration_threshold>
              <soft_cfm>0</soft_cfm>
              <soft_erp>0.2</soft_erp>
              <kp>1e+13</kp>
              <kd>1</kd>
            </bullet>
          </contact>
        </surface> -->
      </collision>
      <sensor name="realsense_camera_front_color" type="camera">
        <pose>0 -0.046 0.004 0 0 0</pose>x
        <camera name="__default__">
          <horizontal_fov>1.047</horizontal_fov>
          <image>
            <width>640</width>
            <height>480</height>
            <format>RGB_INT8</format>
          </image>
          <clip>
            <near>0.1</near>
            <far>100</far>
          </clip>
          <noise>
            <type>gaussian</type>
            <mean>0.0</mean>
            <stddev>0.007</stddev>
          </noise>
        </camera>
        <always_on>1</always_on>
        <update_rate>60</update_rate>
        <visualize>1</visualize>
      </sensor>
      <sensor name="realsense_camera_front_ired1" type="camera">
        <pose>0 -0.06 0.004 0 0 0</pose>
        <camera name="__default__">
          <horizontal_fov>1.047</horizontal_fov>
          <image>
            <width>640</width>
            <height>480</height>
            <format>L_INT8</format>
          </image>
          <clip>
            <near>0.1</near>
            <far>100</far>
          </clip>
          <noise>
            <type>gaussian</type>
            <mean>0.0</mean>
            <stddev>0.007</stddev>
          </noise>
        </camera>
        <always_on>1</always_on>
        <update_rate>60</update_rate>
        <visualize>0</visualize>
      </sensor>
      <sensor name="realsense_camera_front_ired2" type="camera">
        <pose>0 0.01 0.004 0 0 0</pose>
        <camera name="__default__">
          <horizontal_fov>1.047</horizontal_fov>
          <image>
            <width>640</width>
            <height>480</height>
            <format>L_INT8</format>
          </image>
          <clip>
            <near>0.1</near>
            <far>100</far>
          </clip>
          <noise>
            <type>gaussian</type>
            <mean>0.0</mean>
            <stddev>0.007</stddev>
          </noise>
        </camera>
        <always_on>1</always_on>
        <update_rate>60</update_rate>
        <visualize>0</visualize>
      </sensor>
      <sensor name="realsense_camera_front_depth" type="depth">
        <pose>0 -0.03 0.004 0 0 0</pose>
        <camera name="__default__">
          <horizontal_fov>1.047</horizontal_fov>
          <image>
            <width>640</width>
            <height>480</height>
          </image>
          <clip>
            <near>0.1</near>
            <far>100</far>
          </clip>
          <noise>
            <type>gaussian</type>
            <mean>0.0</mean>
            <stddev>0.007</stddev>
          </noise>
        </camera>
        <always_on>1</always_on>
        <update_rate>60</update_rate>
        <visualize>0</visualize>
      </sensor>
    </link>
  </model>
  </model>
</sdf>
