<?xml version="1.0" ?>
<sdf version='1.6'>
  <model name='uuv2'>
    <link name='base_link'>
    <!--
      <self_collide>0</self_collide>
      <velocity_decay/>
      -->
      <pose frame=''>0 0 0 0 0 0</pose>
      <inertial>
        <pose frame=''>0 0 0 0 0 0</pose>
        <mass>1.47</mass>
        <inertia>
          <ixx>0.0024</ixx>
          <ixy>0</ixy>
          <ixz>0</ixz>
          <iyy>0.010717</iyy>
          <iyz>0</iyz>
          <izz>0.010717</izz>
        </inertia>
      </inertial>
      <collision name='base_link_inertia_collision'>
        <pose frame=''>0 0 0 0 1.570796 0</pose>
        <geometry>
          <cylinder>
            <radius>0.03</radius>
            <length>0.36</length>
          </cylinder>
        </geometry>
        <surface>
          <contact>
            <ode>
              <min_depth>0.001</min_depth>
              <max_vel>0</max_vel>
            </ode>
          </contact>
          <friction>
            <ode/>
          </friction>
        </surface>
      </collision>
      <visual name='base_link_inertia_visual'>
        <pose frame=''>0 0 0 0 0 0</pose>
        <geometry>
          <mesh>
            <scale>1 1 1</scale>
            <uri>model://uuv2/meshes/uuv2.stl</uri>
          </mesh>
        </geometry>
        <material>
          <script>
            <name>Gazebo/Grey</name>
            <uri>file://media/materials/scripts/gazebo.material</uri>
          </script>
        </material>
      </visual>
      <gravity>0</gravity>
      <velocity_decay/>
      <!-- Body Frame Visualization -->
      <!--
      <visual name='coordinate_x'>
        <pose frame=''>0.15 0 0 0 1.570796 0</pose>
        <geometry>
          <cylinder>
            <radius>0.0025</radius>
            <length>0.3</length>
          </cylinder>
        </geometry>
        <material>
          <script>
            <name>Gazebo/Red</name>
            <uri>file://media/materials/scripts/gazebo.material</uri>
          </script>
        </material>
      </visual>
      <visual name='coordinate_y'>
        <pose frame=''>0 -0.075 0 1.570796 0 0</pose>
        <geometry>
          <cylinder>
            <radius>0.0025</radius>
            <length>0.15</length>
          </cylinder>
        </geometry>
        <material>
          <script>
            <name>Gazebo/Green</name>
            <uri>file://media/materials/scripts/gazebo.material</uri>
          </script>
        </material>
      </visual>
      <visual name='coordinate_z'>
        <pose frame=''>0 0 -0.075 0 0 0</pose>
        <geometry>
          <cylinder> 
            <radius>0.0025</radius>
            <length>0.15</length>
          </cylinder>
        </geometry>
        <material>
          <script>
            <name>Gazebo/Blue</name>
            <uri>file://media/materials/scripts/gazebo.material</uri>
          </script>
        </material>
      </visual>
      -->
    </link>

    <!--
        A new link is defined which hold the IMU (e.g. acceleration sensors, ...). For the simulation it is positioned
        at the center of the Hippocampus.
        The orientation of the IMU is chosen in regard to the orientation of the Body coordinate system of the
        HippoCampus. PX4 uses the data from the IMU to calculate the orientation. Therefore PX4 assumes a NED (North-
        East-Down) coordinate frame whereas Gazebo uses a ENU (East-North-Up) coordinate frame.
    -->
<!-- IMU link -->
    <link name='uuv2/imu_link'>
      <pose frame=''>0 0 0 0 0 0</pose>
      <!--<pose frame=''>0 0 0 3.1415 0 0</pose>-->
      <inertial>
        <pose frame=''>0 0 0 0 0 0</pose>
        <mass>0.015</mass>
        <inertia>
          <ixx>1e-05</ixx>
          <ixy>0</ixy>
          <ixz>0</ixz>
          <iyy>1e-05</iyy>
          <iyz>0</iyz>
          <izz>1e-05</izz>
        </inertia>
      </inertial>
      <!--
      <gravity>0</gravity>
      <velocity_decay/>
      <self_collide>0</self_collide>
      -->
      <gravity>0</gravity>
    </link>

<!-- IMU joint -->
    <joint name='uuv2/imu_joint' type='revolute'>
      <child>uuv2/imu_link</child>
      <parent>base_link</parent>
      <axis>
        <xyz>1 0 0</xyz>   
        <limit>
          <lower>0</lower>
          <upper>0</upper>
          <effort>0</effort>
          <velocity>0</velocity>
        </limit>
        <dynamics>
          <spring_reference>0</spring_reference>
          <spring_stiffness>0</spring_stiffness>
        </dynamics>
        <use_parent_model_frame>1</use_parent_model_frame>
      </axis>
    </joint>

<!-- Camera link 1 -->
     <link name="camera_link1">
        <inertial>
            <mass>0.01</mass>
        </inertial>
        <gravity>0</gravity>
        <pose>0.1 0 -0.05 0 1.5708 0</pose>
        <sensor type="multicamera" name="stereo_camera">
              <camera name="left">
                <pose>0 0 0 0 0 1.5708</pose>
                <horizontal_fov>1.3962634</horizontal_fov>
                <image>
                  <width>800</width>
                  <height>800</height>
                  <format>R8G8B8</format>
                </image>
                <clip>
                  <near>0.02</near>
                  <far>300</far>
                </clip>
                <noise>
                  <type>gaussian</type>
                  <mean>0.0</mean>
                  <stddev>0.007</stddev>
                </noise>
              </camera>
              <camera name="right">
                <horizontal_fov>1.3962634</horizontal_fov>
                <image>
                  <width>800</width>
                  <height>800</height>
                  <format>R8G8B8</format>
                </image>
                <clip>
                  <near>0.02</near>
                  <far>300</far>
                </clip>
                <noise>
                  <type>gaussian</type>
                  <mean>0.0</mean>
                  <stddev>0.007</stddev>
                </noise>
              </camera>
              <update_rate>30.0</update_rate>
              <visualize>1</visualize>
              <always_on>1</always_on>
              <plugin name="stereo_camera_controller" filename="libgazebo_ros_multicamera.so">
                <alwaysOn>true</alwaysOn>
                <updateRate>0.0</updateRate>
                <cameraName>multisense_sl/camera</cameraName>
                <imageTopicName>image_raw</imageTopicName>
                <cameraInfoTopicName>camera_info</cameraInfoTopicName>
                <frameName>left_camera_optical_frame</frameName>
                <!--<rightFrameName>right_camera_optical_frame</rightFrameName>-->
                <hackBaseline>0.07</hackBaseline>
                <distortionK1>0.0</distortionK1>
                <distortionK2>0.0</distortionK2>
                <distortionK3>0.0</distortionK3>
                <distortionT1>0.0</distortionT1>
                <distortionT2>0.0</distortionT2>
              </plugin>
            </sensor>
    </link>

    <joint type="fixed" name="camera_joint1">
        <child>camera_link1</child>
        <parent>base_link</parent>
    </joint>


<!-- CCW 1-->
<!-- rotor_0 link -->
    <link name='rotor_0'>
      <pose frame=''>-0.05 0.0481 0.0481 0 0 0</pose>
      <inertial>
        <pose frame=''>0 0 0 0 -0 0</pose>
        <mass>0.005</mass>
        <inertia>
          <ixx>9.75e-07</ixx>
          <ixy>0</ixy>
          <ixz>0</ixz>
          <iyy>0.000273104</iyy>
          <iyz>0</iyz>
          <izz>0.000274004</izz>
        </inertia>
      </inertial>
      <collision name='rotor_0_collision'>
        <pose frame=''>0 0 0.02 0 0 0</pose>
        <geometry>
          <cylinder>
            <radius>0.02</radius>
            <length>0.06</length>
          </cylinder>
        </geometry>
        <surface>
          <contact>
            <ode/>
          </contact>
          <friction>
            <ode/>
          </friction>
        </surface>
      </collision>
      <visual name='rotor_0_visual'>
        <pose frame=''>0 0 0 0 0 0</pose>
        <geometry>
          <mesh>
            <scale>1 1 1</scale>
            <uri>model://uuv2/meshes/uuv2_prop.stl</uri>
          </mesh>
        </geometry>
        <material>
          <script>
            <name>Gazebo/Blue</name>
            <uri>file://media/materials/scripts/gazebo.material</uri>
          </script>
        </material>
      </visual>
      <gravity>0</gravity>
      <velocity_decay/>
    </link>

<!-- rotor_0 joint -->
    <joint name='rotor_0_joint' type='revolute'>
      <parent>base_link</parent>
      <child>rotor_0</child>
      <axis>
        <xyz>1 0 0</xyz>
        <limit>
          <lower>-1e+16</lower>
          <upper>1e+16</upper>
        </limit>
        <dynamics>
          <spring_reference>0</spring_reference>
          <spring_stiffness>0</spring_stiffness>
        </dynamics>
        <use_parent_model_frame>1</use_parent_model_frame>
      </axis>
    </joint>

<!-- CW 2 -->
<!-- rotor_1 link -->
    <link name='rotor_1'>
      <pose frame=''>-0.05 -0.0481 0.0481 0 0 0</pose>
      <inertial>
        <pose frame=''>0 0 0 0 -0 0</pose>
        <mass>0.005</mass>
        <inertia>
          <ixx>9.75e-07</ixx>
          <ixy>0</ixy>
          <ixz>0</ixz>
          <iyy>0.000273104</iyy>
          <iyz>0</iyz>
          <izz>0.000274004</izz>
        </inertia>
      </inertial>
      <collision name='rotor_1_collision'>
        <pose frame=''>0 0 0.02 0 0 0</pose>
        <geometry>
          <cylinder>
            <radius>0.02</radius>
            <length>0.06</length>
          </cylinder>
        </geometry>
        <surface>
          <contact>
            <ode/>
          </contact>
          <friction>
            <ode/>
          </friction>
        </surface>
      </collision>
      <visual name='rotor_1_visual'>
        <pose frame=''>0 0 0 0 0 0</pose>
        <geometry>
          <mesh>
            <scale>1 1 1</scale>
            <uri>model://uuv2/meshes/uuv2_prop.stl</uri>
          </mesh>
        </geometry>
        <material>
          <script>
            <name>Gazebo/Blue</name>
            <uri>file://media/materials/scripts/gazebo.material</uri>
          </script>
        </material>
      </visual>
      <gravity>0</gravity>
      <velocity_decay/>
    </link>

<!-- rotor_1 joint -->
    <joint name='rotor_1_joint' type='revolute'>
    <child>rotor_1</child>
      <parent>base_link</parent>
      <axis>
        <xyz>1 0 0</xyz>
        <limit>
          <lower>-1e+16</lower>
          <upper>1e+16</upper>
        </limit>
        <dynamics>
          <spring_reference>0</spring_reference>
          <spring_stiffness>0</spring_stiffness>
        </dynamics>
        <use_parent_model_frame>1</use_parent_model_frame>
      </axis>
    </joint>

<!-- CCW 3 -->
<!-- rotor_2 link -->
    <link name='rotor_2'>
      <pose frame=''>-0.05 -0.0481 -0.0481 0 0 0</pose>
      <inertial>
        <pose frame=''>0 0 0 0 -0 0</pose>
        <mass>0.005</mass>
        <inertia>
          <ixx>9.75e-07</ixx>
          <ixy>0</ixy>
          <ixz>0</ixz>
          <iyy>0.000273104</iyy>
          <iyz>0</iyz>
          <izz>0.000274004</izz>
        </inertia>
      </inertial>
      <collision name='rotor_2_collision'>
        <pose frame=''>0 0 0.02 0 0 0</pose>
        <geometry>
          <cylinder>
            <radius>0.02</radius>
            <length>0.06</length>
          </cylinder>
        </geometry>
        <surface>
          <contact>
            <ode/>
          </contact>
          <friction>
            <ode/>
          </friction>
        </surface>
      </collision>
      <visual name='rotor_2_visual'>
        <pose frame=''>0 0 0 0 0 0</pose>
        <geometry>
          <mesh>
            <scale>1 1 1</scale>
            <uri>model://uuv2/meshes/uuv2_prop.stl</uri>
          </mesh>
        </geometry>
        <material>
          <script>
            <name>Gazebo/Blue</name>
            <uri>file://media/materials/scripts/gazebo.material</uri>
          </script>
        </material>
      </visual>
      <gravity>0</gravity>
      <velocity_decay/>
    </link>

<!-- rotor_2 joint -->
    <joint name='rotor_2_joint' type='revolute'>
      <child>rotor_2</child>
      <parent>base_link</parent> 
      <axis>
        <xyz>1 0 0</xyz>
        <limit>
          <lower>-1e+16</lower>
          <upper>1e+16</upper>
        </limit>
        <dynamics>
          <spring_reference>0</spring_reference>
          <spring_stiffness>0</spring_stiffness>
        </dynamics>
        <use_parent_model_frame>1</use_parent_model_frame>
      </axis>
    </joint>

<!-- CW 4 -->
<!-- rotor_3 link -->
    <link name='rotor_3'>
      <pose frame=''>-0.05 0.0481 -0.0481 0 0 0</pose>
      <inertial>
        <pose frame=''>0 0 0 0 -0 0</pose>
        <mass>0.005</mass>
        <inertia>
          <ixx>9.75e-07</ixx>
          <ixy>0</ixy>
          <ixz>0</ixz>
          <iyy>0.000273104</iyy>
          <iyz>0</iyz>
          <izz>0.000274004</izz>
        </inertia>
      </inertial>
      <collision name='rotor_3_collision'>
        <pose frame=''>0 0 0.02 0 0 0</pose>
        <geometry>
          <cylinder>
            <radius>0.02</radius>
            <length>0.06</length>
          </cylinder>
        </geometry>
        <surface>
          <contact>
            <ode/>
          </contact>
          <friction>
            <ode/>
          </friction>
        </surface>
      </collision>
      <visual name='rotor_3_visual'>
        <pose frame=''>0 0 0 0 0 0</pose>
        <geometry>
          <mesh>
            <scale>1 1 1</scale>
            <uri>model://uuv2/meshes/uuv2_prop.stl</uri>
          </mesh>
        </geometry>
        <material>
          <script>
            <name>Gazebo/Blue</name>
            <uri>file://media/materials/scripts/gazebo.material</uri>
          </script>
        </material>
      </visual>
      <gravity>0</gravity>
      <velocity_decay/>
    </link>

<!-- rotor_3 joint -->
    <joint name='rotor_3_joint' type='revolute'>
      <child>rotor_3</child>
      <parent>base_link</parent> 
      <axis>
        <xyz>1 0 0</xyz>
        <limit>
          <lower>-1e+16</lower>
          <upper>1e+16</upper>
        </limit>
        <dynamics>
          <spring_reference>0</spring_reference>
          <spring_stiffness>0</spring_stiffness>
        </dynamics>
        <use_parent_model_frame>1</use_parent_model_frame>
      </axis>
    </joint>

<!-- Plugins -->
<static>0</static>

<plugin name='rosbag' filename='libgazebo_multirotor_base_plugin.so'>
  <robotNamespace/>
  <linkName>base_link</linkName>
  <rotorVelocitySlowdownSim>0.05</rotorVelocitySlowdownSim>
</plugin>

<plugin name='uuv_forces' filename='libgazebo_uuv_motor_model.so'>
  <robotNamespace/>
  <baseLinkName>base_link</baseLinkName>
  <prop0LinkName>rotor_0</prop0LinkName>
  <prop1LinkName>rotor_1</prop1LinkName>
  <prop2LinkName>rotor_2</prop2LinkName>
  <prop3LinkName>rotor_3</prop3LinkName>
  <turningDirection0>ccw</turningDirection0>
  <turningDirection1>cw</turningDirection1>
  <turningDirection2>ccw</turningDirection2>
  <turningDirection3>cw</turningDirection3>
  <motorForceConstant>8.5</motorForceConstant>
  <motorTorqueConstant>0.0024</motorTorqueConstant>
  <deadZone>0</deadZone>
  <addedMassLinear>1.11 2.8 2.8</addedMassLinear>
  <addedMassAngular>0.00451 0.0163 0.0163</addedMassAngular>
  <dampingLinear>5.39 17.36 17.36</dampingLinear>
  <dampingAngular>0.00114 0.007 0.007</dampingAngular>
  <commandSubTopic>/gazebo/command/motor_speed</commandSubTopic>
</plugin>


<!--
<plugin name='front_right_motor_model' filename='libgazebo_uuv_motor_model.so'>
  <robotNamespace/>
  <jointName>rotor_0_joint</jointName>
  <linkName>rotor_0</linkName>
  <turningDirection>ccw</turningDirection>
  <timeConstantUp>0.0125</timeConstantUp>
  <timeConstantDown>0.025</timeConstantDown>
  <maxRotVelocity>1100</maxRotVelocity>
  <motorConstant>8.54858e-06</motorConstant>
  <momentConstant>0.06</momentConstant>
  <commandSubTopic>/gazebo/command/motor_speed</commandSubTopic>
  <motorNumber>0</motorNumber>
  <rotorDragCoefficient>0.000806428</rotorDragCoefficient>
  <rollingMomentCoefficient>1e-06</rollingMomentCoefficient>
  <motorSpeedPubTopic>/motor_speed/0</motorSpeedPubTopic>
  <rotorVelocitySlowdownSim>0.05</rotorVelocitySlowdownSim>
</plugin>
<plugin name='back_left_motor_model' filename='libgazebo_uuv_motor_model.so'>
  <robotNamespace/>
  <jointName>rotor_1_joint</jointName>
  <linkName>rotor_1</linkName>
  <turningDirection>cw</turningDirection>
  <timeConstantUp>0.0125</timeConstantUp>
  <timeConstantDown>0.025</timeConstantDown>
  <maxRotVelocity>1100</maxRotVelocity>
  <motorConstant>8.54858e-06</motorConstant>
  <momentConstant>0.06</momentConstant>
  <commandSubTopic>/gazebo/command/motor_speed</commandSubTopic>
  <motorNumber>0</motorNumber>
  <rotorDragCoefficient>0.000806428</rotorDragCoefficient>
  <rollingMomentCoefficient>1e-06</rollingMomentCoefficient>
  <motorSpeedPubTopic>/motor_speed/0</motorSpeedPubTopic>
  <rotorVelocitySlowdownSim>0.05</rotorVelocitySlowdownSim>
</plugin>
<plugin name='front_left_motor_model' filename='libgazebo_uuv_motor_model.so'>
  <robotNamespace/>
  <jointName>rotor_2_joint</jointName>
  <linkName>rotor_2</linkName>
  <turningDirection>ccw</turningDirection>
  <timeConstantUp>0.0125</timeConstantUp>
  <timeConstantDown>0.025</timeConstantDown>
  <maxRotVelocity>1100</maxRotVelocity>
  <motorConstant>8.54858e-06</motorConstant>
  <momentConstant>0.06</momentConstant>
  <commandSubTopic>/gazebo/command/motor_speed</commandSubTopic>
  <motorNumber>0</motorNumber>
  <rotorDragCoefficient>0.000806428</rotorDragCoefficient>
  <rollingMomentCoefficient>1e-06</rollingMomentCoefficient>
  <motorSpeedPubTopic>/motor_speed/0</motorSpeedPubTopic>
  <rotorVelocitySlowdownSim>0.05</rotorVelocitySlowdownSim>
</plugin>
<plugin name='back_right_motor_model' filename='libgazebo_uuv_motor_model.so'>
  <robotNamespace/>
  <jointName>rotor_3_joint</jointName>
  <linkName>rotor_3</linkName>
  <turningDirection>cw</turningDirection>
  <timeConstantUp>0.0125</timeConstantUp>
  <timeConstantDown>0.025</timeConstantDown>
  <maxRotVelocity>1100</maxRotVelocity>
  <motorConstant>8.54858e-06</motorConstant>
  <momentConstant>0.06</momentConstant>
  <commandSubTopic>/gazebo/command/motor_speed</commandSubTopic>
  <motorNumber>0</motorNumber>
  <rotorDragCoefficient>0.000806428</rotorDragCoefficient>
  <rollingMomentCoefficient>1e-06</rollingMomentCoefficient>
  <motorSpeedPubTopic>/motor_speed/0</motorSpeedPubTopic>
  <rotorVelocitySlowdownSim>0.05</rotorVelocitySlowdownSim>
</plugin>-->

    <plugin name="gps_plugin" filename="libgazebo_gps_plugin.so">
        <robotNamespace/>
        <gpsNoise>true</gpsNoise>
    </plugin>

<plugin name='magnetometer_plugin' filename='libgazebo_magnetometer_plugin.so'>
  <robotNamespace/>
  <pubRate>20</pubRate>
  <noiseDensity>0.0004</noiseDensity>
  <randomWalk>6.4e-06</randomWalk>
  <biasCorrelationTime>600</biasCorrelationTime>
  <magTopic>/mag</magTopic>
</plugin>

<plugin name='barometer_plugin' filename='libgazebo_barometer_plugin.so'>
  <robotNamespace/>
  <pubRate>10</pubRate>
  <baroTopic>/baro</baroTopic>
</plugin>

<plugin name='mavlink_interface' filename='libgazebo_mavlink_interface.so'>
<robotNamespace/>
<imuSubTopic>/imu</imuSubTopic>
<gpsSubTopic>/gps</gpsSubTopic>
<magSubTopic>/mag</magSubTopic>
<baroSubTopic>/baro</baroSubTopic>
<mavlink_addr>INADDR_ANY</mavlink_addr>
<mavlink_udp_port>14560</mavlink_udp_port>
<mavlink_tcp_port>4560</mavlink_tcp_port>
<serialEnabled>0</serialEnabled>
<serialDevice>/dev/ttyACM0</serialDevice>
<baudRate>921600</baudRate>
<qgc_addr>INADDR_ANY</qgc_addr>
<qgc_udp_port>14550</qgc_udp_port>
<sdk_addr>INADDR_ANY</sdk_addr>
<sdk_udp_port>14540</sdk_udp_port>
<hil_mode>0</hil_mode>
<hil_state_level>0</hil_state_level>
<vehicle_is_tailsitter>0</vehicle_is_tailsitter>
<send_vision_estimation>1</send_vision_estimation>
<send_odometry>0</send_odometry>
<enable_lockstep>1</enable_lockstep>
<use_tcp>1</use_tcp>
  <motorSpeedCommandPubTopic>/gazebo/command/motor_speed</motorSpeedCommandPubTopic>
  <!-- control channels, this way for every channel different settings can be realized -->
  <control_channels>
    <channel name='rotor1'>
      <input_index>0</input_index>
      <input_offset>0</input_offset>
      <input_scaling>1</input_scaling>
      <zero_position_disarmed>0</zero_position_disarmed>
      <zero_position_armed>0</zero_position_armed>
      <joint_control_type>velocity</joint_control_type>
    </channel>
    <channel name='rotor2'>
      <input_index>1</input_index>
      <input_offset>0</input_offset>
      <input_scaling>1</input_scaling>
      <zero_position_disarmed>0</zero_position_disarmed>
      <zero_position_armed>0</zero_position_armed>
      <joint_control_type>velocity</joint_control_type>
    </channel>
    <channel name='rotor3'>
      <input_index>2</input_index>
      <input_offset>0</input_offset>
      <input_scaling>1</input_scaling>
      <zero_position_disarmed>0</zero_position_disarmed>
      <zero_position_armed>0</zero_position_armed>
      <joint_control_type>velocity</joint_control_type>
    </channel>
    <channel name='rotor4'>
      <input_index>3</input_index>
      <input_offset>0</input_offset>
      <input_scaling>1</input_scaling>
      <zero_position_disarmed>0</zero_position_disarmed>
      <zero_position_armed>0</zero_position_armed>
      <joint_control_type>velocity</joint_control_type>
    </channel>
  </control_channels>
</plugin>
<static>0</static>
<plugin name='gazebo_imu_plugin' filename='libgazebo_imu_plugin.so'>
<robotNamespace/>
<linkName>uuv2/imu_link</linkName>
<imuTopic>/imu</imuTopic>
<gyroscopeNoiseDensity>0.0003394</gyroscopeNoiseDensity>
<gyroscopeRandomWalk>3.8785e-05</gyroscopeRandomWalk>
<gyroscopeBiasCorrelationTime>1000.0</gyroscopeBiasCorrelationTime>
<gyroscopeTurnOnBiasSigma>0.0087</gyroscopeTurnOnBiasSigma>
<accelerometerNoiseDensity>0.004</accelerometerNoiseDensity>
<accelerometerRandomWalk>0.006</accelerometerRandomWalk>
<accelerometerBiasCorrelationTime>300.0</accelerometerBiasCorrelationTime>
<accelerometerTurnOnBiasSigma>0.196</accelerometerTurnOnBiasSigma>
</plugin>
  </model>
</sdf>
